[2024-10-17T09:24:11.685+0000] {taskinstance.py:1979} INFO - Dependencies all met for dep_context=non-requeueable deps ti=<TaskInstance: etl_from_local_to_postgres.transform_data manual__2024-10-17T09:24:05.868801+00:00 [queued]>
[2024-10-17T09:24:11.701+0000] {taskinstance.py:1979} INFO - Dependencies all met for dep_context=requeueable deps ti=<TaskInstance: etl_from_local_to_postgres.transform_data manual__2024-10-17T09:24:05.868801+00:00 [queued]>
[2024-10-17T09:24:11.703+0000] {taskinstance.py:2193} INFO - Starting attempt 1 of 1
[2024-10-17T09:24:11.725+0000] {taskinstance.py:2217} INFO - Executing <Task(PythonOperator): transform_data> on 2024-10-17 09:24:05.868801+00:00
[2024-10-17T09:24:11.734+0000] {standard_task_runner.py:60} INFO - Started process 154 to run task
[2024-10-17T09:24:11.738+0000] {standard_task_runner.py:87} INFO - Running: ['***', 'tasks', 'run', 'etl_from_local_to_postgres', 'transform_data', 'manual__2024-10-17T09:24:05.868801+00:00', '--job-id', '644', '--raw', '--subdir', 'DAGS_FOLDER/etl.py', '--cfg-path', '/tmp/tmp_58g5eik']
[2024-10-17T09:24:11.741+0000] {standard_task_runner.py:88} INFO - Job 644: Subtask transform_data
[2024-10-17T09:24:11.814+0000] {task_command.py:423} INFO - Running <TaskInstance: etl_from_local_to_postgres.transform_data manual__2024-10-17T09:24:05.868801+00:00 [running]> on host 9c093e78d1a2
[2024-10-17T09:24:11.922+0000] {taskinstance.py:2513} INFO - Exporting env vars: AIRFLOW_CTX_DAG_OWNER='***' AIRFLOW_CTX_DAG_ID='etl_from_local_to_postgres' AIRFLOW_CTX_TASK_ID='transform_data' AIRFLOW_CTX_EXECUTION_DATE='2024-10-17T09:24:05.868801+00:00' AIRFLOW_CTX_TRY_NUMBER='1' AIRFLOW_CTX_DAG_RUN_ID='manual__2024-10-17T09:24:05.868801+00:00'
[2024-10-17T09:24:12.138+0000] {taskinstance.py:2731} ERROR - Task failed with exception
Traceback (most recent call last):
  File "/home/airflow/.local/lib/python3.10/site-packages/airflow/models/taskinstance.py", line 444, in _execute_task
    result = _execute_callable(context=context, **execute_callable_kwargs)
  File "/home/airflow/.local/lib/python3.10/site-packages/airflow/models/taskinstance.py", line 414, in _execute_callable
    return execute_callable(context=context, **execute_callable_kwargs)
  File "/home/airflow/.local/lib/python3.10/site-packages/airflow/operators/python.py", line 200, in execute
    return_value = self.execute_callable()
  File "/home/airflow/.local/lib/python3.10/site-packages/airflow/operators/python.py", line 217, in execute_callable
    return self.python_callable(*self.op_args, **self.op_kwargs)
  File "/opt/airflow/dags/etl.py", line 37, in transform_data
    float_df['Start Date'] = pd.to_datetime(float_df['Start Date'])
UnboundLocalError: local variable 'float_df' referenced before assignment
[2024-10-17T09:24:12.156+0000] {taskinstance.py:1149} INFO - Marking task as FAILED. dag_id=etl_from_local_to_postgres, task_id=transform_data, execution_date=20241017T092405, start_date=20241017T092411, end_date=20241017T092412
[2024-10-17T09:24:12.174+0000] {standard_task_runner.py:107} ERROR - Failed to execute job 644 for task transform_data (local variable 'float_df' referenced before assignment; 154)
[2024-10-17T09:24:12.223+0000] {local_task_job_runner.py:234} INFO - Task exited with return code 1
[2024-10-17T09:24:12.260+0000] {taskinstance.py:3312} INFO - 0 downstream tasks scheduled from follow-on schedule check
