[2024-10-17T09:27:16.030+0000] {taskinstance.py:1979} INFO - Dependencies all met for dep_context=non-requeueable deps ti=<TaskInstance: etl_from_local_to_postgres.load_data manual__2024-10-17T09:27:09.120265+00:00 [queued]>
[2024-10-17T09:27:16.044+0000] {taskinstance.py:1979} INFO - Dependencies all met for dep_context=requeueable deps ti=<TaskInstance: etl_from_local_to_postgres.load_data manual__2024-10-17T09:27:09.120265+00:00 [queued]>
[2024-10-17T09:27:16.046+0000] {taskinstance.py:2193} INFO - Starting attempt 1 of 1
[2024-10-17T09:27:16.068+0000] {taskinstance.py:2217} INFO - Executing <Task(PythonOperator): load_data> on 2024-10-17 09:27:09.120265+00:00
[2024-10-17T09:27:16.075+0000] {standard_task_runner.py:60} INFO - Started process 218 to run task
[2024-10-17T09:27:16.079+0000] {standard_task_runner.py:87} INFO - Running: ['***', 'tasks', 'run', 'etl_from_local_to_postgres', 'load_data', 'manual__2024-10-17T09:27:09.120265+00:00', '--job-id', '647', '--raw', '--subdir', 'DAGS_FOLDER/etl.py', '--cfg-path', '/tmp/tmpamkswqa_']
[2024-10-17T09:27:16.081+0000] {standard_task_runner.py:88} INFO - Job 647: Subtask load_data
[2024-10-17T09:27:16.142+0000] {task_command.py:423} INFO - Running <TaskInstance: etl_from_local_to_postgres.load_data manual__2024-10-17T09:27:09.120265+00:00 [running]> on host 9c093e78d1a2
[2024-10-17T09:27:16.245+0000] {taskinstance.py:2513} INFO - Exporting env vars: AIRFLOW_CTX_DAG_OWNER='***' AIRFLOW_CTX_DAG_ID='etl_from_local_to_postgres' AIRFLOW_CTX_TASK_ID='load_data' AIRFLOW_CTX_EXECUTION_DATE='2024-10-17T09:27:09.120265+00:00' AIRFLOW_CTX_TRY_NUMBER='1' AIRFLOW_CTX_DAG_RUN_ID='manual__2024-10-17T09:27:09.120265+00:00'
[2024-10-17T09:27:16.355+0000] {taskinstance.py:2731} ERROR - Task failed with exception
Traceback (most recent call last):
  File "/home/airflow/.local/lib/python3.10/site-packages/airflow/models/taskinstance.py", line 444, in _execute_task
    result = _execute_callable(context=context, **execute_callable_kwargs)
  File "/home/airflow/.local/lib/python3.10/site-packages/airflow/models/taskinstance.py", line 414, in _execute_callable
    return execute_callable(context=context, **execute_callable_kwargs)
  File "/home/airflow/.local/lib/python3.10/site-packages/airflow/operators/python.py", line 200, in execute
    return_value = self.execute_callable()
  File "/home/airflow/.local/lib/python3.10/site-packages/airflow/operators/python.py", line 217, in execute_callable
    return self.python_callable(*self.op_args, **self.op_kwargs)
  File "/opt/airflow/dags/etl.py", line 89, in load_data
    conn = hook.get_conn()
  File "/home/airflow/.local/lib/python3.10/site-packages/airflow/providers/postgres/hooks/postgres.py", line 131, in get_conn
    conn = deepcopy(self.connection or self.get_connection(conn_id))
  File "/home/airflow/.local/lib/python3.10/site-packages/airflow/hooks/base.py", line 82, in get_connection
    conn = Connection.get_connection_from_secrets(conn_id)
  File "/home/airflow/.local/lib/python3.10/site-packages/airflow/models/connection.py", line 514, in get_connection_from_secrets
    raise AirflowNotFoundException(f"The conn_id `{conn_id}` isn't defined")
airflow.exceptions.AirflowNotFoundException: The conn_id `project_connection` isn't defined
[2024-10-17T09:27:16.365+0000] {taskinstance.py:1149} INFO - Marking task as FAILED. dag_id=etl_from_local_to_postgres, task_id=load_data, execution_date=20241017T092709, start_date=20241017T092716, end_date=20241017T092716
[2024-10-17T09:27:16.383+0000] {standard_task_runner.py:107} ERROR - Failed to execute job 647 for task load_data (The conn_id `project_connection` isn't defined; 218)
[2024-10-17T09:27:16.405+0000] {local_task_job_runner.py:234} INFO - Task exited with return code 1
[2024-10-17T09:27:16.424+0000] {taskinstance.py:3312} INFO - 0 downstream tasks scheduled from follow-on schedule check
