[2024-10-18T08:47:05.866+0000] {taskinstance.py:1979} INFO - Dependencies all met for dep_context=non-requeueable deps ti=<TaskInstance: etl_from_local_to_postgres.load_data scheduled__2024-10-17T00:00:00+00:00 [queued]>
[2024-10-18T08:47:05.881+0000] {taskinstance.py:1979} INFO - Dependencies all met for dep_context=requeueable deps ti=<TaskInstance: etl_from_local_to_postgres.load_data scheduled__2024-10-17T00:00:00+00:00 [queued]>
[2024-10-18T08:47:05.882+0000] {taskinstance.py:2193} INFO - Starting attempt 1 of 1
[2024-10-18T08:47:05.902+0000] {taskinstance.py:2217} INFO - Executing <Task(PythonOperator): load_data> on 2024-10-17 00:00:00+00:00
[2024-10-18T08:47:05.908+0000] {standard_task_runner.py:60} INFO - Started process 85 to run task
[2024-10-18T08:47:05.912+0000] {standard_task_runner.py:87} INFO - Running: ['***', 'tasks', 'run', 'etl_from_local_to_postgres', 'load_data', 'scheduled__2024-10-17T00:00:00+00:00', '--job-id', '686', '--raw', '--subdir', 'DAGS_FOLDER/etl.py', '--cfg-path', '/tmp/tmp4zn7a02z']
[2024-10-18T08:47:05.913+0000] {standard_task_runner.py:88} INFO - Job 686: Subtask load_data
[2024-10-18T08:47:05.972+0000] {task_command.py:423} INFO - Running <TaskInstance: etl_from_local_to_postgres.load_data scheduled__2024-10-17T00:00:00+00:00 [running]> on host 9c093e78d1a2
[2024-10-18T08:47:06.084+0000] {taskinstance.py:2513} INFO - Exporting env vars: AIRFLOW_CTX_DAG_OWNER='***' AIRFLOW_CTX_DAG_ID='etl_from_local_to_postgres' AIRFLOW_CTX_TASK_ID='load_data' AIRFLOW_CTX_EXECUTION_DATE='2024-10-17T00:00:00+00:00' AIRFLOW_CTX_TRY_NUMBER='1' AIRFLOW_CTX_DAG_RUN_ID='scheduled__2024-10-17T00:00:00+00:00'
[2024-10-18T08:47:06.231+0000] {base.py:83} INFO - Using connection ID 'project_connection' for task execution.
[2024-10-18T08:47:06.241+0000] {taskinstance.py:2731} ERROR - Task failed with exception
Traceback (most recent call last):
  File "/home/airflow/.local/lib/python3.10/site-packages/airflow/models/taskinstance.py", line 444, in _execute_task
    result = _execute_callable(context=context, **execute_callable_kwargs)
  File "/home/airflow/.local/lib/python3.10/site-packages/airflow/models/taskinstance.py", line 414, in _execute_callable
    return execute_callable(context=context, **execute_callable_kwargs)
  File "/home/airflow/.local/lib/python3.10/site-packages/airflow/operators/python.py", line 200, in execute
    return_value = self.execute_callable()
  File "/home/airflow/.local/lib/python3.10/site-packages/airflow/operators/python.py", line 217, in execute_callable
    return self.python_callable(*self.op_args, **self.op_kwargs)
  File "/opt/airflow/dags/etl.py", line 93, in load_data
    conn = hook.get_conn()
  File "/home/airflow/.local/lib/python3.10/site-packages/airflow/providers/postgres/hooks/postgres.py", line 161, in get_conn
    self.conn = psycopg2.connect(**conn_args)
  File "/home/airflow/.local/lib/python3.10/site-packages/psycopg2/__init__.py", line 122, in connect
    conn = _connect(dsn, connection_factory=connection_factory, **kwasync)
psycopg2.OperationalError: connection to server at "host.docker.internal" (192.168.65.2), port 5433 failed: Connection refused
	Is the server running on that host and accepting TCP/IP connections?

[2024-10-18T08:47:06.257+0000] {taskinstance.py:1149} INFO - Marking task as FAILED. dag_id=etl_from_local_to_postgres, task_id=load_data, execution_date=20241017T000000, start_date=20241018T084705, end_date=20241018T084706
[2024-10-18T08:47:06.272+0000] {standard_task_runner.py:107} ERROR - Failed to execute job 686 for task load_data (connection to server at "host.docker.internal" (192.168.65.2), port 5433 failed: Connection refused
	Is the server running on that host and accepting TCP/IP connections?
; 85)
[2024-10-18T08:47:06.286+0000] {local_task_job_runner.py:234} INFO - Task exited with return code 1
[2024-10-18T08:47:06.304+0000] {taskinstance.py:3312} INFO - 0 downstream tasks scheduled from follow-on schedule check
