[2024-10-17T09:19:11.884+0000] {taskinstance.py:1979} INFO - Dependencies all met for dep_context=non-requeueable deps ti=<TaskInstance: etl_from_local_to_postgres.transform_data scheduled__2024-10-16T00:00:00+00:00 [queued]>
[2024-10-17T09:19:11.899+0000] {taskinstance.py:1979} INFO - Dependencies all met for dep_context=requeueable deps ti=<TaskInstance: etl_from_local_to_postgres.transform_data scheduled__2024-10-16T00:00:00+00:00 [queued]>
[2024-10-17T09:19:11.900+0000] {taskinstance.py:2193} INFO - Starting attempt 1 of 1
[2024-10-17T09:19:11.925+0000] {taskinstance.py:2217} INFO - Executing <Task(PythonOperator): transform_data> on 2024-10-16 00:00:00+00:00
[2024-10-17T09:19:11.938+0000] {standard_task_runner.py:60} INFO - Started process 85 to run task
[2024-10-17T09:19:11.944+0000] {standard_task_runner.py:87} INFO - Running: ['***', 'tasks', 'run', 'etl_from_local_to_postgres', 'transform_data', 'scheduled__2024-10-16T00:00:00+00:00', '--job-id', '642', '--raw', '--subdir', 'DAGS_FOLDER/etl.py', '--cfg-path', '/tmp/tmp9vzfy3wx']
[2024-10-17T09:19:11.946+0000] {standard_task_runner.py:88} INFO - Job 642: Subtask transform_data
[2024-10-17T09:19:12.026+0000] {task_command.py:423} INFO - Running <TaskInstance: etl_from_local_to_postgres.transform_data scheduled__2024-10-16T00:00:00+00:00 [running]> on host 9c093e78d1a2
[2024-10-17T09:19:12.138+0000] {taskinstance.py:2513} INFO - Exporting env vars: AIRFLOW_CTX_DAG_OWNER='***' AIRFLOW_CTX_DAG_ID='etl_from_local_to_postgres' AIRFLOW_CTX_TASK_ID='transform_data' AIRFLOW_CTX_EXECUTION_DATE='2024-10-16T00:00:00+00:00' AIRFLOW_CTX_TRY_NUMBER='1' AIRFLOW_CTX_DAG_RUN_ID='scheduled__2024-10-16T00:00:00+00:00'
[2024-10-17T09:19:12.154+0000] {taskinstance.py:2731} ERROR - Task failed with exception
Traceback (most recent call last):
  File "/home/airflow/.local/lib/python3.10/site-packages/airflow/models/taskinstance.py", line 444, in _execute_task
    result = _execute_callable(context=context, **execute_callable_kwargs)
  File "/home/airflow/.local/lib/python3.10/site-packages/airflow/models/taskinstance.py", line 414, in _execute_callable
    return execute_callable(context=context, **execute_callable_kwargs)
  File "/home/airflow/.local/lib/python3.10/site-packages/airflow/operators/python.py", line 200, in execute
    return_value = self.execute_callable()
  File "/home/airflow/.local/lib/python3.10/site-packages/airflow/operators/python.py", line 217, in execute_callable
    return self.python_callable(*self.op_args, **self.op_kwargs)
  File "/opt/airflow/dags/etl.py", line 35, in transform_data
    clickup_df['Date'] = pd.to_datetime(clickup_df['Date'])
UnboundLocalError: local variable 'clickup_df' referenced before assignment
[2024-10-17T09:19:12.170+0000] {taskinstance.py:1149} INFO - Marking task as FAILED. dag_id=etl_from_local_to_postgres, task_id=transform_data, execution_date=20241016T000000, start_date=20241017T091911, end_date=20241017T091912
[2024-10-17T09:19:12.190+0000] {standard_task_runner.py:107} ERROR - Failed to execute job 642 for task transform_data (local variable 'clickup_df' referenced before assignment; 85)
[2024-10-17T09:19:12.225+0000] {local_task_job_runner.py:234} INFO - Task exited with return code 1
[2024-10-17T09:19:12.253+0000] {taskinstance.py:3312} INFO - 0 downstream tasks scheduled from follow-on schedule check
