[2024-10-17T09:31:01.738+0000] {taskinstance.py:1979} INFO - Dependencies all met for dep_context=non-requeueable deps ti=<TaskInstance: etl_from_local_to_postgres.load_data manual__2024-10-17T09:30:55.272207+00:00 [queued]>
[2024-10-17T09:31:01.753+0000] {taskinstance.py:1979} INFO - Dependencies all met for dep_context=requeueable deps ti=<TaskInstance: etl_from_local_to_postgres.load_data manual__2024-10-17T09:30:55.272207+00:00 [queued]>
[2024-10-17T09:31:01.754+0000] {taskinstance.py:2193} INFO - Starting attempt 1 of 1
[2024-10-17T09:31:01.777+0000] {taskinstance.py:2217} INFO - Executing <Task(PythonOperator): load_data> on 2024-10-17 09:30:55.272207+00:00
[2024-10-17T09:31:01.785+0000] {standard_task_runner.py:60} INFO - Started process 330 to run task
[2024-10-17T09:31:01.788+0000] {standard_task_runner.py:87} INFO - Running: ['***', 'tasks', 'run', 'etl_from_local_to_postgres', 'load_data', 'manual__2024-10-17T09:30:55.272207+00:00', '--job-id', '653', '--raw', '--subdir', 'DAGS_FOLDER/etl.py', '--cfg-path', '/tmp/tmpnxl0dt81']
[2024-10-17T09:31:01.789+0000] {standard_task_runner.py:88} INFO - Job 653: Subtask load_data
[2024-10-17T09:31:01.847+0000] {task_command.py:423} INFO - Running <TaskInstance: etl_from_local_to_postgres.load_data manual__2024-10-17T09:30:55.272207+00:00 [running]> on host 9c093e78d1a2
[2024-10-17T09:31:01.930+0000] {taskinstance.py:2513} INFO - Exporting env vars: AIRFLOW_CTX_DAG_OWNER='***' AIRFLOW_CTX_DAG_ID='etl_from_local_to_postgres' AIRFLOW_CTX_TASK_ID='load_data' AIRFLOW_CTX_EXECUTION_DATE='2024-10-17T09:30:55.272207+00:00' AIRFLOW_CTX_TRY_NUMBER='1' AIRFLOW_CTX_DAG_RUN_ID='manual__2024-10-17T09:30:55.272207+00:00'
[2024-10-17T09:31:02.006+0000] {base.py:83} INFO - Using connection ID 'project_connection' for task execution.
[2024-10-17T09:31:02.144+0000] {base.py:83} INFO - Using connection ID 'project_connection' for task execution.
[2024-10-17T09:31:02.341+0000] {base.py:83} INFO - Using connection ID 'project_connection' for task execution.
[2024-10-17T09:31:02.461+0000] {taskinstance.py:2731} ERROR - Task failed with exception
Traceback (most recent call last):
  File "/home/airflow/.local/lib/python3.10/site-packages/airflow/models/taskinstance.py", line 444, in _execute_task
    result = _execute_callable(context=context, **execute_callable_kwargs)
  File "/home/airflow/.local/lib/python3.10/site-packages/airflow/models/taskinstance.py", line 414, in _execute_callable
    return execute_callable(context=context, **execute_callable_kwargs)
  File "/home/airflow/.local/lib/python3.10/site-packages/airflow/operators/python.py", line 200, in execute
    return_value = self.execute_callable()
  File "/home/airflow/.local/lib/python3.10/site-packages/airflow/operators/python.py", line 217, in execute_callable
    return self.python_callable(*self.op_args, **self.op_kwargs)
  File "/opt/airflow/dags/etl.py", line 91, in load_data
    cursor.executemany(df_insert_sql, df_values)
psycopg2.errors.InvalidDatetimeFormat: invalid input syntax for type timestamp: "NaT"
LINE 1: ...cc241882428', '5f689933491e884156235c0b988c35e5', 'NaT'::tim...
                                                             ^

[2024-10-17T09:31:02.472+0000] {taskinstance.py:1149} INFO - Marking task as FAILED. dag_id=etl_from_local_to_postgres, task_id=load_data, execution_date=20241017T093055, start_date=20241017T093101, end_date=20241017T093102
[2024-10-17T09:31:02.488+0000] {standard_task_runner.py:107} ERROR - Failed to execute job 653 for task load_data (invalid input syntax for type timestamp: "NaT"
LINE 1: ...cc241882428', '5f689933491e884156235c0b988c35e5', 'NaT'::tim...
                                                             ^
; 330)
[2024-10-17T09:31:02.533+0000] {local_task_job_runner.py:234} INFO - Task exited with return code 1
[2024-10-17T09:31:02.552+0000] {taskinstance.py:3312} INFO - 0 downstream tasks scheduled from follow-on schedule check
